<?xml version="1.0" encoding="utf-8" ?>
<robot name="fanuc-rm10ia" xmlns:xacro="http://www.ros.org/wiki/xacro">
    <!--************************************************BASE_LINK********************************************-->
    <link name="base_link">
        <visual>
            <origin xyz="0 0 0" rpy="0 0 0" />
            <geometry>
                <mesh filename="package://fanuc_description/fanuc_meshes/visual/link_0.dae" />
            </geometry>
            <material name="" />
        </visual>
        <collision>
            <origin xyz="0 0 0" rpy="0 0 0" />
            <geometry>
                <mesh filename="package://fanuc_description/fanuc_meshes/collision/link_0.stl" />
            </geometry>
        </collision>
        
<inertial>
            <mass value="0.1" />
            <inertia ixx="0.03" iyy="0.03" izz="0.03" ixy="0.0" ixz="0.0" iyz="0.0" />
        </inertial>

    </link>
    <!--************************************************LINK 1********************************************-->
    <link name="link1">
        <visual>
            <origin xyz="0 0 0" rpy="0 0 0" />
            <geometry>
                <mesh filename="package://fanuc_description/fanuc_meshes/visual/link_1.dae" />
            </geometry>
            <material name="" />
        </visual>
        <collision>
            <origin xyz="0 0 0" rpy="0 0 0" />
            <geometry>
                <mesh filename="package://fanuc_description/fanuc_meshes/collision/link_1.stl" />
            </geometry>
        </collision>
        
<inertial>
            <mass value="0.1" />
            <inertia ixx="0.03" iyy="0.03" izz="0.03" ixy="0.0" ixz="0.0" iyz="0.0" />
        </inertial>

    </link>
    <joint name="joint1" type="revolute">
        <!--Joint properties-->
        <origin xyz="0 0 0" rpy="0 0 0" />
        <parent link="base_link" />
        <child link="link1" />
        <axis xyz="0 0 1" />
        <limit lower="-3.2288" upper="3.2288" effort="0" velocity="0" />
    </joint>
    <!--************************************************LINK 2********************************************-->
    <link name="link2">
        <visual>
            <origin xyz="-0.15 -0.525 0" rpy="-1.5708 0 0" />
            <geometry>
                <mesh filename="package://fanuc_description/fanuc_meshes/visual/link_2.dae" />
            </geometry>
            <material name="" />
        </visual>
        <collision>
            <origin xyz="-0.15 -0.525 0" rpy="-1.5708 0 0" />
            <geometry>
                <mesh filename="package://fanuc_description/fanuc_meshes/collision/link_2.stl" />
            </geometry>
        </collision>
        
<inertial>
            <mass value="0.1" />
            <inertia ixx="0.03" iyy="0.03" izz="0.03" ixy="0.0" ixz="0.0" iyz="0.0" />
        </inertial>

    </link>
    <joint name="joint2" type="revolute">
        <!--Joint properties-->
        <origin xyz="0.15 0 0.525" rpy="1.5708 0 0" />
        <parent link="link1" />
        <child link="link2" />
        <axis xyz="0 0 1" />
        <limit lower="-1.7453" upper="2.792527" effort="0" velocity="0" />
    </joint>
    <!--************************************************LINK 3********************************************-->
    <link name="link3">
        <visual>
            <origin xyz="-1.315 0.15 0" rpy="-1.5708 0 -1.5708" />
            <geometry>
                <mesh filename="package://fanuc_description/fanuc_meshes/visual/link_3.dae" />
            </geometry>
            <material name="" />
        </visual>
        <collision>
            <origin xyz="-1.315 0.15 0" rpy="-1.5708 0 -1.5708" />
            <geometry>
                <mesh filename="package://fanuc_description/fanuc_meshes/collision/link_3.stl" />
            </geometry>
        </collision>
        
<inertial>
            <mass value="0.1" />
            <inertia ixx="0.03" iyy="0.03" izz="0.03" ixy="0.0" ixz="0.0" iyz="0.0" />
        </inertial>

    </link>
    <joint name="joint3" type="revolute">
        <!--Joint properties-->
        <origin xyz="0 0.79 0" rpy="0 0 1.5708" />
        <parent link="link2" />
        <child link="link3" />
        <axis xyz="0 0 1" />
        <limit lower="-3.228859" upper="4.810826" effort="0" velocity="0" />
    </joint>
    <!--************************************************LINK 4********************************************-->
    <link name="link4">
        <visual>
            <origin xyz="-1.465 0 -0.15" rpy="-3.14 -1.5708 0" />
            <geometry>
                <mesh filename="package://fanuc_description/fanuc_meshes/visual/link_4.dae" />
            </geometry>
            <material name="" />
        </visual>
        <collision>
            <origin xyz="-1.465 0 -0.15" rpy="-3.14 -1.5708 0" />
            <geometry>
                <mesh filename="package://fanuc_description/fanuc_meshes/collision/link_4.stl" />
            </geometry>
        </collision>
        
<inertial>
            <mass value="0.1" />
            <inertia ixx="0.03" iyy="0.03" izz="0.03" ixy="0.0" ixz="0.0" iyz="0.0" />
        </inertial>

    </link>
    <joint name="joint4" type="revolute">
        <!--Joint properties-->
        <origin xyz="0.15 0 0" rpy="1.5708 0 0" />
        <parent link="link3" />
        <child link="link4" />
        <axis xyz="0 0 1" />
        <limit lower="-3.4906" upper="3.4906" effort="0" velocity="0" />
    </joint>
    <!--************************************************LINK 5********************************************-->
    <link name="link5">
        <visual>
            <origin xyz="-1.465 1.01 0" rpy="-1.5708 0 -1.5708" />
            <geometry>
                <mesh filename="package://fanuc_description/fanuc_meshes/visual/link_5.dae" />
            </geometry>
            <material name="" />
        </visual>
        <collision>
            <origin xyz="-1.465 1.01 0" rpy="-1.5708 0 -1.5708" />
            <geometry>
                <mesh filename="package://fanuc_description/fanuc_meshes/collision/link_5.stl" />
            </geometry>
        </collision>
        
<inertial>
            <mass value="0.1" />
            <inertia ixx="0.03" iyy="0.03" izz="0.03" ixy="0.0" ixz="0.0" iyz="0.0" />
        </inertial>

    </link>
    <joint name="joint5" type="revolute">
        <!--Joint properties-->
        <origin xyz="0 0 0.86" rpy="-1.5708 0 0" />
        <parent link="link4" />
        <child link="link5" />
        <axis xyz="0 0 1" />
        <limit lower="-2.4434" upper="2.4434" effort="0" velocity="0" />
    </joint>
    <!--************************************************LINK 6********************************************-->
    <link name="link6">
        <visual>
            <origin xyz="0 0 0.1" rpy="0 0 0" />
            <geometry>
                <mesh filename="package://fanuc_description/fanuc_meshes/visual/link_6.dae" />
            </geometry>
            <material name="" />
        </visual>
        <collision>
            <origin xyz="0 0 0.1" rpy="0 0 0" />
            <geometry>
                <mesh filename="package://fanuc_description/fanuc_meshes/collision/link_6.stl" />
            </geometry>
        </collision>
        
<inertial>
            <mass value="0.1" />
            <inertia ixx="0.03" iyy="0.03" izz="0.03" ixy="0.0" ixz="0.0" iyz="0.0" />
        </inertial>

    </link>
    <joint name="joint6" type="revolute">
        <!--Joint properties-->
        <origin xyz="0 0 0" rpy="1.5708 0 0" />
        <parent link="link5" />
        <child link="link6" />
        <axis xyz="0 0 1" />
        <limit lower="-47.12389" upper="47.12389" effort="0" velocity="0" />
    </joint>
    <!--************************************************ flange ********************************************-->
    <link name="flange" />
    <joint name="flange" type="fixed">
        <!--Joint properties-->
        <origin xyz="0 0 0.1" rpy="0 0 0" />
        <parent link="link6" />
        <child link="flange" />
    </joint>
    
<transmission name="trans_joint1">
        <type>transmission_interface/SimpleTransmission</type>
        <joint name="joint1">
            <hardwareInterface>hardware_interface/EffortJointInterface</hardwareInterface>
        </joint>
        <actuator name="joint1_motor">
            <hardwareInterface>hardware_interface/EffortJointInterface</hardwareInterface>
            <mechanicalReduction>1</mechanicalReduction>
        </actuator>
    </transmission>
    <transmission name="trans_joint2">
        <type>transmission_interface/SimpleTransmission</type>
        <joint name="joint2">
            <hardwareInterface>hardware_interface/EffortJointInterface</hardwareInterface>
        </joint>
        <actuator name="joint2_motor">
            <hardwareInterface>hardware_interface/EffortJointInterface</hardwareInterface>
            <mechanicalReduction>1</mechanicalReduction>
        </actuator>
    </transmission>
    <transmission name="trans_joint3">
        <type>transmission_interface/SimpleTransmission</type>
        <joint name="joint3">
            <hardwareInterface>hardware_interface/EffortJointInterface</hardwareInterface>
        </joint>
        <actuator name="joint3_motor">
            <hardwareInterface>hardware_interface/EffortJointInterface</hardwareInterface>
            <mechanicalReduction>1</mechanicalReduction>
        </actuator>
    </transmission>
    <transmission name="trans_joint4">
        <type>transmission_interface/SimpleTransmission</type>
        <joint name="joint4">
            <hardwareInterface>hardware_interface/EffortJointInterface</hardwareInterface>
        </joint>
        <actuator name="joint4_motor">
            <hardwareInterface>hardware_interface/EffortJointInterface</hardwareInterface>
            <mechanicalReduction>1</mechanicalReduction>
        </actuator>
    </transmission>
    <transmission name="trans_joint5">
        <type>transmission_interface/SimpleTransmission</type>
        <joint name="joint5">
            <hardwareInterface>hardware_interface/EffortJointInterface</hardwareInterface>
        </joint>
        <actuator name="joint5_motor">
            <hardwareInterface>hardware_interface/EffortJointInterface</hardwareInterface>
            <mechanicalReduction>1</mechanicalReduction>
        </actuator>
    </transmission>
    <transmission name="trans_joint6">
        <type>transmission_interface/SimpleTransmission</type>
        <joint name="joint6">
            <hardwareInterface>hardware_interface/EffortJointInterface</hardwareInterface>
        </joint>
        <actuator name="joint6_motor">
            <hardwareInterface>hardware_interface/EffortJointInterface</hardwareInterface>
            <mechanicalReduction>1</mechanicalReduction>
        </actuator>
    </transmission>
    <gazebo>
        <plugin name="gazebo_ros_control" filename="libgazebo_ros_control.so">
            <robotNamespace>/</robotNamespace>
        </plugin>
    </gazebo>
</robot>